<?xml version="1.0"?>
<robot name="atr_mp_rov" xmlns:xacro="http://www.ros.org/wiki/xacro">

  <!-- ── Properties from Phase 1 ──────────────────────────────── -->
  <xacro:property name="mass"  value="119.0"/>
  <xacro:property name="ixx"   value="6.91"/>
  <xacro:property name="iyy"   value="37.73"/>
  <xacro:property name="izz"   value="36.20"/>
  <xacro:property name="ixy"   value="-0.24"/>
  <xacro:property name="ixz"   value="-0.60"/>
  <xacro:property name="iyz"   value="-0.02"/>

  <!-- ── Display vs simulation mode ───────────────────────────── -->
  <!-- Pass fixed_to_world:=true for RViz2 display launch only    -->
  <!-- Gazebo launch omits this arg — defaults to false            -->
  <xacro:arg name="fixed_to_world" default="false"/>

  <!-- CoM Z: display frame (0.22) vs Gazebo NED frame (-0.1292) -->
  <xacro:property name="com_z"
    value="${0.22 if '$(arg fixed_to_world)' == 'true' else -0.1292}"/>

  <!-- Inertial rpy: display needs flip, Gazebo must have no rotation -->
  <xacro:property name="com_rpy"
    value="${'3.142 0 0' if '$(arg fixed_to_world)' == 'true' else '0 0 0'}"/>

  <!-- Tag to find the mesh directory for both display and simulation. 
  The xacro arg allows the path to be overridden if needed, but by default 
  it uses the meshes directory in this package. -->
  <xacro:arg name="mesh_path" default="package://atr_rov_description/meshes"/>

  <!-- ── World anchor — RViz2 display only ────────────────────── -->
  <xacro:if value="$(arg fixed_to_world)">
    <link name="world"/>
    <joint name="world_to_base" type="fixed">
      <parent link="world"/>
      <child  link="base_link"/>
      <origin xyz="0 0 0" rpy="0 0 0"/>
    </joint>
  </xacro:if>

  <link name="base_link">
    <inertial>
      <!-- CoM offset — switches between display and physics frame -->
      <origin xyz="-0.11 -0.001 ${com_z}" rpy="0 0 0"/>
      <mass value="${mass}"/>
      <inertia ixx="${ixx}" ixy="${ixy}" ixz="${ixz}"
               iyy="${iyy}" iyz="${iyz}" izz="${izz}"/>
    </inertial>

    <!-- Single STL file used for both visual and collision -->
    <!-- scale="0.001 0.001 0.001" converts mm to metres if SolidWorks exported in mm -->
    <visual>
      <origin xyz="0.1975 0.35 0.175" rpy=" 3.142 0 0"/>
      <geometry>
        <mesh filename="$(arg mesh_path)/4mm_houston_scaled_16mb.stl"
              scale="0.001 0.001 0.001"/>
      </geometry>
      <material name="light_yellow">
        <color rgba="1.0 1.0 0.66 1.0"/>
      </material>
    </visual>
    <collision>
      <origin xyz="-0.11 -0.001 0.22" rpy=" 0 0 0"/>
      <geometry>
        <box size="1.97 0.6 0.1038"/>
      </geometry>
    </collision>
  </link>

  <!-- ── Sensor frames (fixed links at physical mounting positions) ── -->
  <link name="ins_link"/>
  <joint name="ins_joint" type="fixed">
    <parent link="base_link"/>
    <child  link="ins_link"/>
    <origin xyz="-0.03428 -0.02276 0.18475" rpy="0 0 0"/>
  </joint>

  <link name="dvl_link"/>
  <joint name="dvl_joint" type="fixed">
    <parent link="base_link"/>
    <child  link="dvl_link"/>
    <origin xyz="-0.841 -0.009 0.18" rpy="0 0 0"/>
  </joint>

  <link name="depth_link"/>
  <joint name="depth_joint" type="fixed">
    <parent link="base_link"/>
    <child  link="depth_link"/>
    <origin xyz="0.3 -0.01 0.17" rpy="0 0 0"/>
  </joint>

  <link name="sonar_link"/>
  <joint name="sonar_joint" type="fixed">
    <parent link="base_link"/>
    <child  link="sonar_link"/>
    <origin xyz="0.8 -0.005 0.29" rpy="0 0 0"/>
  </joint>

  <!-- ── Thruster frames (propeller disc centres from Phase 1 TAM) ── -->
  <!--
    Thruster plugin applies force along +Z of the thruster link frame.
    Rotations rotate the thruster link frame relative to base_link:

    T1–T4 (vertical, push down):
      rpy="0 0 0" — thruster Z aligns with base_link Z (downward in NED)

    T5–T6 (surge, push forward):
      rpy="0 -1.5708 0" — pitch -90° rotates thruster Z to point along +X

    T7–T8 (sway, push port = -Y):
      rpy="0 0 1.5708" — yaw +90° rotates thruster Z to point along -Y

    Note: verify directions in validation test V3. If a thruster moves
    the ROV in the wrong direction, negate the force command in the
    bridge or flip the rotation by π (add 3.14159 to the relevant angle).
  -->
  <link name="thruster_1_link">
    <inertial>
      <mass value="0.5"/>
      <inertia ixx="0.001" ixy="0" ixz="0"
              iyy="0.001" iyz="0" izz="0.001"/>
    </inertial>
  </link>
  <joint name="thruster_1_joint" type="continuous">
    <parent link="base_link"/>
    <child  link="thruster_1_link"/>
    <origin xyz="0.371365 -0.15363 0.09" rpy="0 0 0"/>
    <axis xyz="0 0 1"/>
    <!-- <limit lower="-1e9" upper="1e9" effort="100" velocity="1000"/> -->
  </joint>

  <link name="thruster_2_link">
    <inertial>
      <mass value="0.5"/>
      <inertia ixx="0.001" ixy="0" ixz="0"
              iyy="0.001" iyz="0" izz="0.001"/>
    </inertial>
  </link>
  <joint name="thruster_2_joint" type="continuous">
    <parent link="base_link"/>
    <child  link="thruster_2_link"/>
    <origin xyz="0.371365 0.14037 0.09" rpy="0 0 0"/>
    <axis xyz="0 0 1"/>
    <!-- <limit lower="-1e9" upper="1e9" effort="100" velocity="1000"/> -->
  </joint>

  <link name="thruster_3_link">
    <inertial>
      <mass value="0.5"/>
      <inertia ixx="0.001" ixy="0" ixz="0"
              iyy="0.001" iyz="0" izz="0.001"/>
    </inertial>
  </link>
  <joint name="thruster_3_joint" type="continuous">
    <parent link="base_link"/>
    <child  link="thruster_3_link"/>
    <origin xyz="-0.514 0.14037 0.09" rpy="0 0 0"/>
    <axis xyz="0 0 1"/>
    <!-- <limit lower="-1e9" upper="1e9" effort="100" velocity="1000"/> -->
  </joint>

  <link name="thruster_4_link">
    <inertial>
      <mass value="0.5"/>
      <inertia ixx="0.001" ixy="0" ixz="0"
              iyy="0.001" iyz="0" izz="0.001"/>
    </inertial>
  </link>
  <joint name="thruster_4_joint" type="continuous">
    <parent link="base_link"/>
    <child  link="thruster_4_link"/>
    <origin xyz="-0.514 -0.15363 0.09" rpy="0 0 0"/>
    <axis xyz="0 0 1"/>
    <!-- <limit lower="-1e9" upper="1e9" effort="100" velocity="1000"/> -->
  </joint>

  <link name="thruster_5_link">
    <inertial>
      <mass value="0.5"/>
      <inertia ixx="0.001" ixy="0" ixz="0"
              iyy="0.001" iyz="0" izz="0.001"/>
    </inertial>
  </link>
  <joint name="thruster_5_joint" type="continuous">
    <parent link="base_link"/>
    <child  link="thruster_5_link"/>
    <origin xyz="0.11 -0.148 0.32" rpy="0 0 0"/>
    <axis xyz="1 0 0"/>
    <!-- <limit lower="-1e9" upper="1e9" effort="100" velocity="1000"/> -->
  </joint>

  <link name="thruster_6_link">
    <inertial>
      <mass value="0.5"/>
      <inertia ixx="0.001" ixy="0" ixz="0"
              iyy="0.001" iyz="0" izz="0.001"/>
    </inertial>
  </link>
  <joint name="thruster_6_joint" type="continuous">
    <parent link="base_link"/>
    <child  link="thruster_6_link"/>
    <origin xyz="0.11 0.13 0.32" rpy="0 0 0"/>
    <axis xyz="1 0 0"/>
    <!-- <limit lower="-1e9" upper="1e9" effort="100" velocity="1000"/> -->
  </joint>

  <link name="thruster_7_link">
    <inertial>
      <mass value="0.5"/>
      <inertia ixx="0.001" ixy="0" ixz="0"
              iyy="0.001" iyz="0" izz="0.001"/>
    </inertial>
  </link>
  <joint name="thruster_7_joint" type="continuous">
    <parent link="base_link"/>
    <child  link="thruster_7_link"/>
    <origin xyz="-0.36 0.075 0.379" rpy="0 0 0"/>
    <axis xyz="0 1 0"/>
    <!-- <limit lower="-1e9" upper="1e9" effort="100" velocity="1000"/> -->
  </joint>

  <link name="thruster_8_link">
    <inertial>
      <mass value="0.5"/>
      <inertia ixx="0.001" ixy="0" ixz="0"
              iyy="0.001" iyz="0" izz="0.001"/>
    </inertial>
  </link>
  <joint name="thruster_8_joint" type="continuous">
    <parent link="base_link"/>
    <child  link="thruster_8_link"/>
    <origin xyz="0.215 0.075 0.379" rpy="0 0 0"/>
    <axis xyz="0 1 0"/>
    <!-- <limit lower="-1e9" upper="1e9" effort="100" velocity="1000"/> -->
  </joint>

  <!-- ── Gazebo Fortress — Hydrodynamics plugin ────────────────── -->
  <gazebo>
    <plugin filename="ignition-gazebo-hydrodynamics-system"
            name="ignition::gazebo::systems::Hydrodynamics">
      <link_name>base_link</link_name>
      <!-- Added mass (Phase 1 Section 5.1) -->
      <!-- yDotV/zDotW capped below vehicle mass (119 kg): Ignition applies added
           mass as an explicit force; M_A > m causes acceleration divergence. -->
      <!-- <yDotV>-160.95</yDotV> -->
      <!-- <zDotW>-160.95</zDotW> -->
      <xDotU>-53.65</xDotU>
        <yDotV>-95.0</yDotV>
        <zDotW>-95.0</zDotW>
      <kDotP>-0.005</kDotP>
      <mDotQ>-1.0</mDotQ>
      <nDotR>-1.0</nDotR>
      <!-- Linear damping (Phase 1 Section 5.2) -->
      <xU>-40.43</xU>
      <yV>-171.37</yV>
      <zW>-348.87</zW>
      <kP>-80.0</kP>
      <mQ>-120.0</mQ>
      <nR>-120.0</nR>
      <!-- Quadratic damping (Phase 1 Section 5.3) -->
      <xUabsU>-135.93</xUabsU>
      <yVabsV>-453.10</yVabsV>
      <zWabsW>-582.14</zWabsW>
      <kPabsP>0.0</kPabsP>
      <mQabsQ>0.0</mQabsQ>
      <nRabsR>0.0</nRabsR>
    </plugin>
  </gazebo>

  <!-- ── Gazebo Fortress — Thruster plugins (T1–T8) ────────────── -->
  <gazebo>
    <plugin 
      filename="ignition-gazebo-thruster-system"
      name="ignition::gazebo::systems::Thruster">
      <namespace>atr_mp_rov</namespace>
      <joint_name>thruster_1_joint</joint_name>
      <thrust_coefficient>1.0</thrust_coefficient>
      <fluid_density>1000</fluid_density>
      <propeller_diameter>0.1</propeller_diameter>
      <velocity_control>true</velocity_control>
      <topic>thrusters/1/force</topic>
    </plugin>
  </gazebo>

  <gazebo>
    <plugin filename="ignition-gazebo-thruster-system"
            name="ignition::gazebo::systems::Thruster">
      <namespace>atr_mp_rov</namespace>
      <joint_name>thruster_2_joint</joint_name>
      <thrust_coefficient>1.0</thrust_coefficient>
      <fluid_density>1000</fluid_density>
      <propeller_diameter>0.1</propeller_diameter>
      <velocity_control>true</velocity_control>
      <topic>thrusters/2/force</topic>
    </plugin>
  </gazebo>

  <gazebo>
    <plugin filename="ignition-gazebo-thruster-system"
            name="ignition::gazebo::systems::Thruster">
      <namespace>atr_mp_rov</namespace>
      <joint_name>thruster_3_joint</joint_name>
      <thrust_coefficient>1.0</thrust_coefficient>
      <fluid_density>1000</fluid_density>
      <propeller_diameter>0.1</propeller_diameter>
      <velocity_control>true</velocity_control>
      <topic>thrusters/3/force</topic>
    </plugin>
  </gazebo>

  <gazebo>
    <plugin filename="ignition-gazebo-thruster-system"
            name="ignition::gazebo::systems::Thruster">
      <namespace>atr_mp_rov</namespace>
      <joint_name>thruster_4_joint</joint_name>
      <thrust_coefficient>1.0</thrust_coefficient>
      <fluid_density>1000</fluid_density>
      <propeller_diameter>0.1</propeller_diameter>
      <velocity_control>true</velocity_control>
      <topic>thrusters/4/force</topic>
    </plugin>
  </gazebo>

  <gazebo>
    <plugin filename="ignition-gazebo-thruster-system"
            name="ignition::gazebo::systems::Thruster">
      <namespace>atr_mp_rov</namespace>
      <joint_name>thruster_5_joint</joint_name>
      <thrust_coefficient>1.0</thrust_coefficient>
      <fluid_density>1000</fluid_density>
      <propeller_diameter>0.1</propeller_diameter>
      <velocity_control>true</velocity_control>
      <topic>thrusters/5/force</topic>
    </plugin>
  </gazebo>

  <gazebo>
    <plugin filename="ignition-gazebo-thruster-system"
            name="ignition::gazebo::systems::Thruster">
      <namespace>atr_mp_rov</namespace>
      <joint_name>thruster_6_joint</joint_name>
      <thrust_coefficient>1.0</thrust_coefficient>
      <fluid_density>1000</fluid_density>
      <propeller_diameter>0.1</propeller_diameter>
      <velocity_control>true</velocity_control>
      <topic>thrusters/6/force</topic>
    </plugin>
  </gazebo>

  <gazebo>
    <plugin filename="ignition-gazebo-thruster-system"
            name="ignition::gazebo::systems::Thruster">
      <namespace>atr_mp_rov</namespace>
      <joint_name>thruster_7_joint</joint_name>
      <thrust_coefficient>1.0</thrust_coefficient>
      <fluid_density>1000</fluid_density>
      <propeller_diameter>0.1</propeller_diameter>
      <velocity_control>true</velocity_control>
      <topic>thrusters/7/force</topic>
    </plugin>
  </gazebo>

  <gazebo>
    <plugin filename="ignition-gazebo-thruster-system"
            name="ignition::gazebo::systems::Thruster">
      <namespace>atr_mp_rov</namespace>
      <joint_name>thruster_8_joint</joint_name>
      <thrust_coefficient>1.0</thrust_coefficient>
      <fluid_density>1000</fluid_density>
      <propeller_diameter>0.1</propeller_diameter>
      <velocity_control>true</velocity_control>
      <topic>thrusters/8/force</topic>
    </plugin>
  </gazebo>
  <!-- Repeat plugin block for T2–T8 changing joint_name and topic -->

  <!-- ── Gazebo Fortress — Odometry publisher ──────────────────── -->
  <gazebo>
    <plugin filename="ignition-gazebo-odometry-publisher-system"
            name="ignition::gazebo::systems::OdometryPublisher">
      <odom_topic>/nav/ins_odom</odom_topic>
      <robot_base_frame>base_link</robot_base_frame>
      <odom_frame>odom</odom_frame>
      <publish_rate>50</publish_rate>
    </plugin>
  </gazebo>

  <!-- ── Gazebo Fortress — IMU sensor ──────────────────────────── -->
  <gazebo reference="ins_link">
    <sensor name="ins_imu" type="imu">
      <always_on>true</always_on>
      <update_rate>50</update_rate>
      <imu>
        <angular_velocity>
          <x><noise type="gaussian"><mean>0</mean><stddev>0.001</stddev></noise></x>
          <y><noise type="gaussian"><mean>0</mean><stddev>0.001</stddev></noise></y>
          <z><noise type="gaussian"><mean>0</mean><stddev>0.001</stddev></noise></z>
        </angular_velocity>
        <linear_acceleration>
          <x><noise type="gaussian"><mean>0</mean><stddev>0.01</stddev></noise></x>
          <y><noise type="gaussian"><mean>0</mean><stddev>0.01</stddev></noise></y>
          <z><noise type="gaussian"><mean>0</mean><stddev>0.01</stddev></noise></z>
        </linear_acceleration>
      </imu>
      <plugin filename="ignition-gazebo-imu-system"
              name="ignition::gazebo::systems::Imu"/>
    </sensor>
  </gazebo>

  <!-- ── Gazebo Fortress — Air pressure (depth) sensor ─────────── -->
  <gazebo reference="depth_link">
    <sensor name="depth_sensor" type="air_pressure">
      <always_on>true</always_on>
      <update_rate>50</update_rate>
      <air_pressure>
        <pressure>
          <noise type="gaussian"><mean>0</mean><stddev>20</stddev></noise>
        </pressure>
      </air_pressure>
      <!-- <plugin filename="ignition-gazebo-air-pressure-system"
              name="ignition::gazebo::systems::AirPressure"/> -->
    </sensor>
  </gazebo>

  <!-- ── Gazebo Fortress — Sonar (GPU lidar) ───────────────────── -->
  <gazebo reference="sonar_link">
    <sensor name="sonar" type="gpu_lidar">
      <always_on>true</always_on>
      <update_rate>10</update_rate>
      <lidar>
        <scan>
          <horizontal>
            <samples>360</samples>
            <resolution>1</resolution>
            <min_angle>-3.14159</min_angle>
            <max_angle>3.14159</max_angle>
          </horizontal>
        </scan>
        <range>
          <min>0.3</min><max>30.0</max><resolution>0.01</resolution>
        </range>
        <noise type="gaussian"><mean>0</mean><stddev>0.05</stddev></noise>
      </lidar>
      <!-- No plugin block here — Sensors system goes in world SDF -->
    </sensor>
  </gazebo>

</robot>